Workbook

Sheet 매출계획
A1: ㈜큐테크코리아 · 매출 계획 (2026–2030)
A2: 설치(하드웨어) 매출 + 데이터 기반 반복매출(AI구독·유지보수) 결합 모델 | 단위: 억원, 단가: 억원/노드
A4: ■ 핵심 가정 (조정 가능)
A5: 반복매출 = 당년 매출(지하관로 제외) × 연도별 반복율(↓ 표, 덱 IR p.20 기준)
A6: └ AI구독(SaaS) 비중 / 유지보수(E&M) 비중 | E6: 0.48 | F6: = | G6: =1-E6 -> 0.52
A7: 유형 범례: | C7: 확정 | D7: 파이프라인 | E7: 업사이드
A9: 구분 | B9: 세부 수요처 | C9: 유형 | D9: 단가 | E9: 2026년 | G9: 2027년 | I9: 2028년 | K9: 2029년 | M9: 2030년 | O9: 비고
E10: 수량 | F10: 매출 | G10: 수량 | H10: 매출 | I10: 수량 | J10: 매출 | K10: 수량 | L10: 매출 | M10: 수량 | N10: 매출
A11: 맨홀 모니터링 | B11: 지자체 강남구/은평구 | C11: 파이프라인 | D11: 0.05 | E11: 20 | F11: =E11*$D11 -> 1 | G11: 20 | H11: =G11*$D11 -> 1 | I11: 20 | J11: =I11*$D11 -> 1 | K11: 20 | L11: =K11*$D11 -> 1 | M11: 20 | N11: =M11*$D11 -> 1
B12: 지자체 구로구/노원구 | C12: 파이프라인 | D12: 0.05 | E12: 20 | F12: =E12*$D12 -> 1 | G12: 80 | H12: =G12*$D12 -> 4 | I12: 80 | J12: =I12*$D12 -> 4 | K12: 100 | L12: =K12*$D12 -> 5 | M12: 120 | N12: =M12*$D12 -> 6
B13: 지자체 남양주 | C13: 파이프라인 | D13: 0.05 | E13: 40 | F13: =E13*$D13 -> 2 | G13: 100 | H13: =G13*$D13 -> 5 | I13: 300 | J13: =I13*$D13 -> 15 | K13: 300 | L13: =K13*$D13 -> 15 | M13: 0 | N13: =M13*$D13 -> 0
B14: 지자체 서산 | C14: 파이프라인 | D14: 0.05 | E14: 60 | F14: =E14*$D14 -> 3 | G14: 200 | H14: =G14*$D14 -> 10 | I14: 100 | J14: =I14*$D14 -> 5 | K14: 0 | L14: =K14*$D14 -> 0 | M14: 0 | N14: =M14*$D14 -> 0
B15: 지자체 논산/사천/속초 | C15: 파이프라인 | D15: 0.05 | E15: 60 | F15: =E15*$D15 -> 3 | G15: 300 | H15: =G15*$D15 -> 15 | I15: 600 | J15: =I15*$D15 -> 30 | K15: 800 | L15: =K15*$D15 -> 40 | M15: 1000 | N15: =M15*$D15 -> 50
B16: 지자체 대구/부천/수원 등 | C16: 파이프라인 | D16: 0.05 | E16: 0 | F16: =E16*$D16 -> 0 | G16: 60 | H16: =G16*$D16 -> 3 | I16: 200 | J16: =I16*$D16 -> 10 | K16: 600 | L16: =K16*$D16 -> 30 | M16: 1000 | N16: =M16*$D16 -> 50
B17: 군부대 해군사관학교 | C17: 확정 | D17: 0.05 | E17: 40 | F17: =E17*$D17 -> 2 | G17: 40 | H17: =G17*$D17 -> 2 | I17: 40 | J17: =I17*$D17 -> 2 | K17: 40 | L17: =K17*$D17 -> 2 | M17: 60 | N17: =M17*$D17 -> 3
B18: 혁신조달 조달청 | C18: 파이프라인 | D18: 0.05 | E18: 100 | F18: =E18*$D18 -> 5 | G18: 140 | H18: =G18*$D18 -> 7 | I18: 240 | J18: =I18*$D18 -> 12 | K18: 240 | L18: =K18*$D18 -> 12 | M18: 300 | N18: =M18*$D18 -> 15
B19: 수출 말레이/독일/싱가폴 | C19: 업사이드 | D19: 0.05 | E19: 0 | F19: =E19*$D19 -> 0 | G19: 0 | H19: =G19*$D19 -> 0 | I19: 200 | J19: =I19*$D19 -> 10 | K19: 400 | L19: =K19*$D19 -> 20 | M19: 900 | N19: =M19*$D19 -> 45
B20: 맨홀 모니터링 소계 | E20: =SUM(E11:E19) -> 340 | F20: =SUM(F11:F19) -> 17 | G20: =SUM(G11:G19) -> 940 | H20: =SUM(H11:H19) -> 47 | I20: =SUM(I11:I19) -> 1780 | J20: =SUM(J11:J19) -> 89 | K20: =SUM(K11:K19) -> 2500 | L20: =SUM(L11:L19) -> 125 | ... N20: =SUM(N11:N19) -> 170
A21: 물순환 조성사업 | B21: 안동시/수자원공사 | C21: 확정 | D21: 0.05 | E21: 200 | F21: =E21*$D21 -> 10 | G21: 400 | H21: =G21*$D21 -> 20 | I21: 400 | J21: =I21*$D21 -> 20 | K21: 0 | L21: =K21*$D21 -> 0 | M21: 0 | N21: =M21*$D21 -> 0
B22: 순천,나주 등 지자체 | C22: 파이프라인 | D22: 0.05 | E22: 0 | F22: =E22*$D22 -> 0 | G22: 200 | H22: =G22*$D22 -> 10 | I22: 1200 | J22: =I22*$D22 -> 60 | K22: 1400 | L22: =K22*$D22 -> 70 | M22: 2000 | N22: =M22*$D22 -> 100
B23: 물순환 조성사업 소계 | E23: =SUM(E21:E22) -> 200 | F23: =SUM(F21:F22) -> 10 | G23: =SUM(G21:G22) -> 600 | H23: =SUM(H21:H22) -> 30 | I23: =SUM(I21:I22) -> 1600 | J23: =SUM(J21:J22) -> 80 | K23: =SUM(K21:K22) -> 1400 | L23: =SUM(L21:L22) -> 70 | ... N23: =SUM(N21:N22) -> 100
A24: 지하관로 모니터링 | B24: 울산산업단지 | C24: 확정 | D24: 0.1 | E24: 200 | F24: =E24*$D24 -> 20 | G24: 100 | H24: =G24*$D24 -> 10 | I24: 100 | J24: =I24*$D24 -> 10 | K24: 0 | L24: =K24*$D24 -> 0 | M24: 0 | N24: =M24*$D24 -> 0
B25: SK E&S (민간) | C25: 업사이드 | D25: 0.1 | E25: 20 | F25: =E25*$D25 -> 2 | G25: 100 | H25: =G25*$D25 -> 10 | I25: 400 | J25: =I25*$D25 -> 40 | K25: 700 | L25: =K25*$D25 -> 70 | M25: 2000 | N25: =M25*$D25 -> 200
B26: 타 산업단지 등 | C26: 파이프라인 | D26: 0.1 | E26: 0 | F26: =E26*$D26 -> 0 | G26: 0 | H26: =G26*$D26 -> 0 | I26: 200 | J26: =I26*$D26 -> 20 | K26: 500 | L26: =K26*$D26 -> 50 | M26: 1000 | N26: =M26*$D26 -> 100
B27: 수출 미국/사우디/멕시코 | C27: 업사이드 | D27: 0.12 | E27: 0 | F27: =E27*$D27 -> 0 | G27: 10 | H27: =G27*$D27 -> 1.2 | I27: 100 | J27: =I27*$D27 -> 12 | K27: 1000 | L27: =K27*$D27 -> 120 | M27: 2800 | N27: =M27*$D27 -> 336
B28: 지하관로 모니터링 소계 | E28: =SUM(E24:E27) -> 220 | F28: =SUM(F24:F27) -> 22 | G28: =SUM(G24:G27) -> 210 | H28: =SUM(H24:H27) -> 21.2 | I28: =SUM(I24:I27) -> 800 | J28: =SUM(J24:J27) -> 82 | K28: =SUM(K24:K27) -> 2200 | L28: =SUM(L24:L27) -> 240 | ... N28: =SUM(N24:N27) -> 636
A29: 스마트 병기고 | B29: 육군 (탄약고/총기고) | C29: 파이프라인 | D29: 0.006 | E29: 800 | F29: =E29*$D29 -> 4.8 | G29: 3000 | H29: =G29*$D29 -> 18 | I29: 3000 | J29: =I29*$D29 -> 18 | K29: 3000 | L29: =K29*$D29 -> 18 | M29: 3000 | N29: =M29*$D29 -> 18
B30: 공군/해군 | C30: 확정 | D30: 0.006 | E30: 0 | F30: =E30*$D30 -> 0 | G30: 2000 | H30: =G30*$D30 -> 12 | I30: 3000 | J30: =I30*$D30 -> 18 | K30: 3000 | L30: =K30*$D30 -> 18 | M30: 3000 | N30: =M30*$D30 -> 18
B31: 수출 말레이 | C31: 업사이드 | D31: 0.008 | E31: 0 | F31: =E31*$D31 -> 0 | G31: 2000 | H31: =G31*$D31 -> 16 | I31: 4000 | J31: =I31*$D31 -> 32 | K31: 5000 | L31: =K31*$D31 -> 40 | M31: 10000 | N31: =M31*$D31 -> 80
B32: 스마트 병기고 소계 | E32: =SUM(E29:E31) -> 800 | F32: =SUM(F29:F31) -> 4.8 | G32: =SUM(G29:G31) -> 7000 | H32: =SUM(H29:H31) -> 46 | I32: =SUM(I29:I31) -> 10000 | J32: =SUM(J29:J31) -> 68 | K32: =SUM(K29:K31) -> 11000 | L32: =SUM(L29:L31) -> 76 | ... N32: =SUM(N29:N31) -> 116
A33: 전남·광주 통합안전플랫폼 | B33: 광주시 (직접매출분) | C33: 파이프라인 | D33: 50 | E33: 2 | F33: =E33*$D33 -> 100 | G33: 5 | H33: =G33*$D33 -> 250 | I33: 6 | J33: =I33*$D33 -> 300 | K33: 9 | L33: =K33*$D33 -> 450 | M33: 10 | N33: =M33*$D33 -> 500
B34: 전남·광주 통합안전플랫폼 소계 | E34: =SUM(E33:E33) -> 2 | F34: =SUM(F33:F33) -> 100 | G34: =SUM(G33:G33) -> 5 | H34: =SUM(H33:H33) -> 250 | I34: =SUM(I33:I33) -> 6 | J34: =SUM(J33:J33) -> 300 | K34: =SUM(K33:K33) -> 9 | L34: =SUM(L33:L33) -> 450 | ... N34: =SUM(N33:N33) -> 500
B35: 설치매출 계 (Hardware) | F35: =F20+F23+F28+F32+F34 -> 153.8 | H35: =H20+H23+H28+H32+H34 -> 394.2 | J35: =J20+J23+J28+J32+J34 -> 619 | L35: =L20+L23+L28+L32+L34 -> 961 | N35: =N20+N23+N28+N32+N34 -> 1522
B36: 반복매출 산정 기준 (당년·지하관로 제외) | F36: =F35-F28 -> 131.8 | H36: =H35-H28 -> 373 | J36: =J35-J28 -> 537 | L36: =L35-L28 -> 721 | N36: =N35-N28 -> 886
B37: 반복매출율 (당년 대비) | F37: 0 | H37: 0.1 | J37: 0.25 | L37: 0.35 | N37: 0.45
B38: 유지보수 (E&M) | F38: =F36*F37*$G$6 -> 0 | H38: =H36*H37*$G$6 -> 19.396 | J38: =J36*J37*$G$6 -> 69.81 | L38: =L36*L37*$G$6 -> 131.222 | N38: =N36*N37*$G$6 -> 207.324
B39: AI 구독 (SaaS · ARR) | F39: =F36*F37*$E$6 -> 0 | H39: =H36*H37*$E$6 -> 17.904 | J39: =J36*J37*$E$6 -> 64.44 | L39: =L36*L37*$E$6 -> 121.128 | N39: =N36*N37*$E$6 -> 191.376
B40: 반복매출 계 (Recurring) | F40: =F38+F39 -> 0 | H40: =H38+H39 -> 37.3 | J40: =J38+J39 -> 134.25 | L40: =L38+L39 -> 252.35 | N40: =N38+N39 -> 398.7
B41: 총매출 계 | F41: =F35+F40 -> 153.8 | H41: =H35+H40 -> 431.5 | J41: =J35+J40 -> 753.25 | L41: =L35+L40 -> 1213.35 | N41: =N35+N40 -> 1920.7
A43: ※ 설치매출=수량×단가(회사 데이터 보존). 반복매출=‘산정기준(당년·지하관로 제외)’ × ‘반복매출율(당년 대비, 덱 IR p.20)’ → 유지보수52%·AI구독48% 분배. 노란 칸(반복매출율 행·E6)만 조정하면 전체 재계산. 각 행 이름 셀 메모에 산식 예시 수록.
...

Sheet 요약
A1: 매출 요약 & 덱 정합성
A2: 단위: 억원
A4: 구분 | B4: 2026 | C4: 2027 | D4: 2028 | E4: 2029 | F4: 2030 | G4: 5년 누적
A5: 설치매출 (Hardware) | B5: =매출계획!F35 -> 153.8 | C5: =매출계획!H35 -> 394.2 | D5: =매출계획!J35 -> 619 | E5: =매출계획!L35 -> 961 | F5: =매출계획!N35 -> 1522 | G5: =B5+C5+D5+E5+F5 -> 3650
A6: 유지보수 (E&M) | B6: =매출계획!F38 -> 0 | C6: =매출계획!H38 -> 19.396 | D6: =매출계획!J38 -> 69.81 | E6: =매출계획!L38 -> 131.222 | F6: =매출계획!N38 -> 207.324 | G6: =B6+C6+D6+E6+F6 -> 427.752
A7: AI 구독 (SaaS·ARR) | B7: =매출계획!F39 -> 0 | C7: =매출계획!H39 -> 17.904 | D7: =매출계획!J39 -> 64.44 | E7: =매출계획!L39 -> 121.128 | F7: =매출계획!N39 -> 191.376 | G7: =B7+C7+D7+E7+F7 -> 394.848
A8: 총매출 | B8: =매출계획!F41 -> 153.8 | C8: =매출계획!H41 -> 431.5 | D8: =매출계획!J41 -> 753.25 | E8: =매출계획!L41 -> 1213.35 | F8: =매출계획!N41 -> 1920.7 | G8: =B8+C8+D8+E8+F8 -> 4472.6
A9: 전년대비 성장률 | B9: – | C9: =C8/B8-1 -> 1.8055917 | D9: =D8/C8-1 -> 0.74565469 | E9: =E8/D8-1 -> 0.61081978 | F9: =F8/E8-1 -> 0.58297276
A12: 매출 구성 비중 (2028E) | E12: IM(덱) 대비 정합
A13: 항목 | B13: 2028 매출 | C13: 비중 | E13: 연도 | F13: 본 모델 (Base) | G13: 덱 (Target) | H13: 차이
A14: Hardware (설치) | B14: =매출계획!J35 -> 619 | C14: =B14/$B$17 -> 0.82177232 | E14: 2026 | F14: =매출계획!F41 -> 153.8 | G14: 154 | H14: =F14-G14 -> -0.2
A15: SaaS (AI구독) | B15: =매출계획!J39 -> 64.44 | C15: =B15/$B$17 -> 0.085549286 | E15: 2027 | F15: =매출계획!H41 -> 431.5 | G15: 440 | H15: =F15-G15 -> -8.5
A16: Engineering (E&M) | B16: =매출계획!J38 -> 69.81 | C16: =B16/$B$17 -> 0.092678394 | E16: 2028 | F16: =매출계획!J41 -> 753.25 | G16: 800 | H16: =F16-G16 -> -46.75
A17: 합계 | B17: =SUM(B14:B16) -> 753.25 | C17: =SUM(C14:C16) -> 1 | E17: 2029 | F17: =매출계획!L41 -> 1213.35 | G17: 1220 | H17: =F17-G17 -> -6.65
E18: 2030 | F18: =매출계획!N41 -> 1920.7 | G18: 1920 | H18: =F18-G18 -> 0.7
A20: 설치매출 유형 구성 (확정 / 파이프라인 / 업사이드)
A21: 유형 | B21: 2026 | C21: 2027 | D21: 2028 | E21: 2029 | F21: 2030 | G21: 5년 누적
A22: 확정 | B22: =SUMIF(매출계획!$C$11:$C$34,$A22,매출계획!F$11:F$34) -> 32 | C22: =SUMIF(매출계획!$C$11:$C$34,$A22,매출계획!H$11:H$34) -> 44 | D22: =SUMIF(매출계획!$C$11:$C$34,$A22,매출계획!J$11:J$34) -> 50 | E22: =SUMIF(매출계획!$C$11:$C$34,$A22,매출계획!L$11:L$34) -> 20 | F22: =SUMIF(매출계획!$C$11:$C$34,$A22,매출계획!N$11:N$34) -> 21 | G22: =B22+C22+D22+E22+F22 -> 167
A23: 파이프라인 | B23: =SUMIF(매출계획!$C$11:$C$34,$A23,매출계획!F$11:F$34) -> 119.8 | C23: =SUMIF(매출계획!$C$11:$C$34,$A23,매출계획!H$11:H$34) -> 323 | D23: =SUMIF(매출계획!$C$11:$C$34,$A23,매출계획!J$11:J$34) -> 475 | E23: =SUMIF(매출계획!$C$11:$C$34,$A23,매출계획!L$11:L$34) -> 691 | F23: =SUMIF(매출계획!$C$11:$C$34,$A23,매출계획!N$11:N$34) -> 840 | G23: =B23+C23+D23+E23+F23 -> 2448.8
A24: 업사이드 | B24: =SUMIF(매출계획!$C$11:$C$34,$A24,매출계획!F$11:F$34) -> 2 | C24: =SUMIF(매출계획!$C$11:$C$34,$A24,매출계획!H$11:H$34) -> 27.2 | D24: =SUMIF(매출계획!$C$11:$C$34,$A24,매출계획!J$11:J$34) -> 94 | E24: =SUMIF(매출계획!$C$11:$C$34,$A24,매출계획!L$11:L$34) -> 250 | F24: =SUMIF(매출계획!$C$11:$C$34,$A24,매출계획!N$11:N$34) -> 661 | G24: =B24+C24+D24+E24+F24 -> 1034.2
A25: 설치 계 | B25: =SUM(B22:B24) -> 153.8 | C25: =SUM(C22:C24) -> 394.2 | D25: =SUM(D22:D24) -> 619 | E25: =SUM(E22:E24) -> 961 | F25: =SUM(F22:F24) -> 1522 | G25: =SUM(G22:G24) -> 3650
A28: 전남·광주 통합안전플랫폼 — 사업 총규모 vs 큐테크 직접매출
A29: 사업 총사업비 (정부) | B29: 5,200억 (국비 3,460 + 지방 1,560) — 토목·디지털트윈 등 포함
A30: 큐테크 직접매출 (5년 합) | B30: =매출계획!F33+매출계획!H33+매출계획!J33+매출계획!L33+매출계획!N33 -> 1600
A31: 성격 | B31: 총사업비는 레퍼런스(시장규모), 직접매출만 본 모델에 계상
A34: 반복율 민감도 — 2028년 (당년 기준, Base→Target)
A35: 반복매출율(2028) | B35: 2028 총매출 | C35: 해석
A36: 0.25 | B36: =매출계획!J35+매출계획!J36*0.25 -> 753.25 | C36: 덱 p.20 표기 (Base)
A37: 0.3 | B37: =매출계획!J35+매출계획!J36*0.3 -> 780.1 | C37: 중간 시나리오
A38: 0.337 | B38: =매출계획!J35+매출계획!J36*0.337 -> 799.969 | C38: 덱 목표 800억 도달
A39: ※ 반복매출을 덱과 동일한 ‘당년 매출 × %’ 방식으로 통일(2026:0/2027:10/2028:25/2029:35/2030:45%). 2028년만 덱 800억(목표) 대비 약 47억 미달이며, 반복율을 약 34%로 올리면 도달.
